Workbook

Sheet Leyenda
A1: APF3 · Matriz de auditoría WCAG 2.1 AA · Colegio Benjamin Barton (prototipo v2.0 → v3.0)
A3: Curso | B3: Interacción Hombre Máquina (100000SI87) · Ingeniería de Sistemas · UTP
A4: Grupo | B4: [Grupo N] — completar
A5: Fecha de auditoría | B5: 30 de octubre de 2026
A6: Alcance | B6: PT1 Inicio (carga, carrusel en reproducción y en pausa); PT2 Admisión (información y llamado a solicitar vacante); PT3 Solicitud de vacante (vacío, error, revisión, confirmación y anulación); PT4 Horarios (pestañas por nivel); PT5 Lista de útiles (pestañas por nivel y descarga); PT6 Contáctenos (vacío, error y envío correcto); PT7 Nivel Primaria (contenido con galería)
A7: Nivel objetivo | B7: WCAG 2.1 nivel AA: 50 criterios (30 A + 20 AA); 26 criterios núcleo evaluados con evidencia.
A8: Métodos | B8: Automático: axe-core 4.10.2 (etiquetas wcag2a, wcag2aa, wcag21a, wcag21aa) en 19 páginas. Manual: criterio por criterio, contraste con la fórmula WCAG, zoom 200 %, viewport 320 px, espaciado de texto, simulación de deuteranopía (Machado et al., 2009). Tecnologías de apoyo: recorrido con teclado y registro del árbol de accesibilidad; sesión con NVDA pendiente/ver hoja Validación.
A9: Severidad (S) | B9: 4 = bloquea la tarea a un perfil · 3 = rodeo costoso o pide ayuda · 2 = dificultad menor · 1 = cosmético
A10: Alcance (A) | B10: 3 = flujo crítico o patrón global · 2 = varias pantallas · 1 = elemento aislado
A11: Prioridad | B11: S × A (fórmula). Alta ≥ 8 · Media 4–7 · Baja ≤ 3
A12: Celdas amarillas | B12: DATOS DE EJEMPLO (validación con participantes y línea base APF2). Reemplazar con los datos reales de las sesiones del grupo antes de entregar. Las fórmulas se recalculan solas.
A13: Celdas blancas | B13: Resultados medidos en la v2.0 (barton.engie24.com) y en la v3.0 (sitio estático del grupo).

Sheet Matriz WCAG 2.1
A1: Matriz de auditoría WCAG 2.1 AA (Anexo A de la consigna) — una fila por criterio
A2: Prioridad y categoría se calculan con fórmula a partir de S y A. Criterios no núcleo: basta Aplica/No aplica con justificación.
A4: Hallazgo | B4: Principio | C4: Criterio | D4: Nombre | E4: Nivel | F4: Núcleo | G4: Aplica | H4: Método | I4: Pantalla y estado / justificación | J4: Resultado v2.0 | K4: Evidencia v2.0 | L4: Severidad (1-4) | M4: Alcance (1-3) | N4: Prioridad (S×A) | O4: Categoría | P4: Perfiles afectados | Q4: Ajuste | R4: Estado en v3.0 | S4: Evidencia v3.0
A5: H-03 | B5: Perceptible | C5: 1.1.1 | D5: Contenido no textual | E5: A | F5: Sí | G5: Sí | H5: axe + manual | I5: PT1, PT7 | J5: No cumple | K5: Inicio: 81 de 169 imágenes con alt vacío, incluidas fotos informativas; Municipio: 180 de 268. | L5: 3 | M5: 3 | N5: =IF(OR(L5="",M5=""),"",L5*M5) -> 9 | O5: =IF(N5="","",IF(N5>=8,"Alta",IF(N5>=4,"Media","Baja"))) -> Alta | P5: Ceguera, baja visión (lector de pantalla) | Q5: AJ-03 | R5: Cumple | S5: Fotos informativas con alt descriptivo; decorativas con alt="". axe: 0 incumplimientos.
A6: — | B6: Perceptible | C6: 1.2.1 | D6: Solo audio y solo video (grabado) | E6: A | F6: No | G6: No | H6: Manual | I6: No hay contenido solo audio ni solo video. | J6: No aplica | K6: — | N6: =IF(OR(L6="",M6=""),"",L6*M6) | O6: =IF(N6="","",IF(N6>=8,"Alta",IF(N6>=4,"Media","Baja"))) | P6: — | Q6: — | R6: No aplica | S6: —
A7: H-15 | B7: Perceptible | C7: 1.2.2 | D7: Subtítulos (grabado) | E7: A | F7: No | G7: Sí | H7: Manual | I7: PT1 (video institucional) | J7: Parcial | K7: Video de YouTube sin subtítulos activados; solo los automáticos de la plataforma. | L7: 2 | M7: 1 | N7: =IF(OR(L7="",M7=""),"",L7*M7) -> 2 | O7: =IF(N7="","",IF(N7>=8,"Alta",IF(N7>=4,"Media","Baja"))) -> Baja | P7: Sordera, hipoacusia | Q7: AJ-05 | R7: Parcial | S7: Subtítulos activados por defecto (cc_load_policy=1), pero son automáticos y no se han revisado.
A8: H-15 | B8: Perceptible | C8: 1.2.3 | D8: Audiodescripción o medio alternativo (grabado) | E8: A | F8: No | G8: Sí | H8: Manual | I8: PT1 (video institucional) | J8: No cumple | K8: No hay transcripción ni descripción del contenido visual. | L8: 2 | M8: 1 | N8: =IF(OR(L8="",M8=""),"",L8*M8) -> 2 | O8: =IF(N8="","",IF(N8>=8,"Alta",IF(N8>=4,"Media","Baja"))) -> Baja | P8: Ceguera | Q8: — | R8: No cumple | S8: Pendiente: transcripción descriptiva a cargo del colegio (plan de mejora).
A9: — | B9: Perceptible | C9: 1.2.4 | D9: Subtítulos (en directo) | E9: AA | F9: No | G9: No | H9: Manual | I9: No hay transmisiones en directo. | J9: No aplica | K9: — | N9: =IF(OR(L9="",M9=""),"",L9*M9) | O9: =IF(N9="","",IF(N9>=8,"Alta",IF(N9>=4,"Media","Baja"))) | P9: — | Q9: — | R9: No aplica | S9: —
A10: H-15 | B10: Perceptible | C10: 1.2.5 | D10: Audiodescripción (grabado) | E10: AA | F10: No | G10: Sí | H10: Manual | I10: PT1 (video institucional) | J10: No cumple | K10: Sin audiodescripción. | L10: 2 | M10: 1 | N10: =IF(OR(L10="",M10=""),"",L10*M10) -> 2 | O10: =IF(N10="","",IF(N10>=8,"Alta",IF(N10>=4,"Media","Baja"))) -> Baja | P10: Ceguera | Q10: — | R10: No cumple | S10: Pendiente: versión audiodescrita o transcripción (plan de mejora).
A11: H-04 | B11: Perceptible | C11: 1.3.1 | D11: Información y relaciones | E11: A | F11: Sí | G11: Sí | H11: axe + manual + lector | I11: Todas | J11: No cumple | K11: La mayoría de páginas sin h1 (todo h3); Horarios y Útiles con 14 a 17 h1; aria prohibido en 15 elementos. | L11: 3 | M11: 3 | N11: =IF(OR(L11="",M11=""),"",L11*M11) -> 9 | O11: =IF(N11="","",IF(N11>=8,"Alta",IF(N11>=4,"Media","Baja"))) -> Alta | P11: Ceguera (navegación por encabezados), dislexia | Q11: AJ-03 | R11: Cumple | S11: Un h1 por página y 0 saltos de nivel en 10 páginas; fieldset/legend en grupos; tablas con th y scope.
A12: — | B12: Perceptible | C12: 1.3.2 | D12: Secuencia significativa | E12: A | F12: No | G12: Sí | H12: Manual + lector | I12: Todas | J12: Sin barrera observada | K12: — | N12: =IF(OR(L12="",M12=""),"",L12*M12) | O12: =IF(N12="","",IF(N12>=8,"Alta",IF(N12>=4,"Media","Baja"))) | P12: — | Q12: — | R12: Cumple | S12: El orden del DOM coincide con el orden visual.
A13: — | B13: Perceptible | C13: 1.3.3 | D13: Características sensoriales | E13: A | F13: No | G13: Sí | H13: Manual | I13: PT3, PT6 | J13: Sin barrera observada | K13: — | N13: =IF(OR(L13="",M13=""),"",L13*M13) | O13: =IF(N13="","",IF(N13>=8,"Alta",IF(N13>=4,"Media","Baja"))) | P13: — | Q13: — | R13: Cumple | S13: Las instrucciones no dependen de forma, posición ni color.
A14: — | B14: Perceptible | C14: 1.3.4 | D14: Orientación | E14: AA | F14: Sí | G14: Sí | H14: Manual (320 px vertical y horizontal) | I14: Todas | J14: Cumple | K14: El sitio no bloquea la orientación. | N14: =IF(OR(L14="",M14=""),"",L14*M14) | O14: =IF(N14="","",IF(N14>=8,"Alta",IF(N14>=4,"Media","Baja"))) | P14: — | Q14: — | R14: Cumple | S14: Sin bloqueo de orientación; diseño fluido verificado a 320 px y 683 px.
A15: H-12 | B15: Perceptible | C15: 1.3.5 | D15: Identificar el propósito de la entrada | E15: AA | F15: Sí | G15: Sí | H15: Inspección de código | I15: PT3, PT6 | J15: No cumple | K15: Formulario de contacto sin autocomplete; celular como type=text. | L15: 2 | M15: 2 | N15: =IF(OR(L15="",M15=""),"",L15*M15) -> 4 | O15: =IF(N15="","",IF(N15>=8,"Alta",IF(N15>=4,"Media","Baja"))) -> Media | P15: Motora, cognitiva, baja visión | Q15: AJ-10 | R15: Cumple | S15: autocomplete name, email y tel; celular con type=tel e inputmode numérico.
A16: — | B16: Perceptible | C16: 1.4.1 | D16: Uso del color | E16: A | F16: Sí | G16: Sí | H16: Simulación deuteranopia (Machado 2009) + manual | I16: PT1, PT3, PT6 | J16: Cumple | K16: Los errores eran avisos nativos; no se usaba color como único indicador. | N16: =IF(OR(L16="",M16=""),"",L16*M16) | O16: =IF(N16="","",IF(N16>=8,"Alta",IF(N16>=4,"Media","Baja"))) | P16: Daltonismo | Q16: AJ-05 | R16: Cumple | S16: Errores con el prefijo «Error:» y borde grueso; pasos con número y texto; enlaces subrayados.
A17: — | B17: Perceptible | C17: 1.4.2 | D17: Control del audio | E17: A | F17: No | G17: Sí | H17: Manual | I17: PT1 | J17: Sin barrera observada | K17: — | N17: =IF(OR(L17="",M17=""),"",L17*M17) | O17: =IF(N17="","",IF(N17>=8,"Alta",IF(N17>=4,"Media","Baja"))) | P17: — | Q17: — | R17: Cumple | S17: El video no se reproduce solo (fachada con botón).
A18: H-01 | B18: Perceptible | C18: 1.4.3 | D18: Contraste (mínimo) | E18: AA | F18: Sí | G18: Sí | H18: axe + cálculo WCAG | I18: PT1 y pie global | J18: No cumple | K18: Tarjetas de accesos rápidos: #e5e7eb sobre degradado #d3b4c4–#c4a1b5 = 1.53 a 1.86:1; pie #9e9e9e sobre #424242 = 3.75:1. | L18: 4 | M18: 3 | N18: =IF(OR(L18="",M18=""),"",L18*M18) -> 12 | O18: =IF(N18="","",IF(N18>=8,"Alta",IF(N18>=4,"Media","Baja"))) -> Alta | P18: Baja visión, adultos mayores, daltonismo | Q18: AJ-01 | R18: Cumple | S18: Texto principal 12.63:1, secundario 6.26:1, enlaces 5.36:1; velo de la portada calculado para el peor caso (foto blanca): ≥ 4.5:1 en texto pequeño y ≥ 3:1 en el título.
A19: H-13 | B19: Perceptible | C19: 1.4.4 | D19: Cambio de tamaño del texto | E19: AA | F19: Sí | G19: Sí | H19: Zoom 200 % | I19: Todas | J19: Parcial | K19: En pantallas estrechas se ocultaba el texto de la portada. | L19: 2 | M19: 2 | N19: =IF(OR(L19="",M19=""),"",L19*M19) -> 4 | O19: =IF(N19="","",IF(N19>=8,"Alta",IF(N19>=4,"Media","Baja"))) -> Media | P19: Baja visión, adultos mayores | Q19: AJ-04 | R19: Cumple | S19: A 200 % no hay pérdida de contenido ni desborde (0 px) en las 10 páginas medidas.
A20: — | B20: Perceptible | C20: 1.4.5 | D20: Imágenes de texto | E20: AA | F20: No | G20: Sí | H20: Manual | I20: PT1 (mosaico de actividades) | J20: Parcial | K20: Algunas imágenes del sitio oficial son afiches con texto. | N20: =IF(OR(L20="",M20=""),"",L20*M20) | O20: =IF(N20="","",IF(N20>=8,"Alta",IF(N20>=4,"Media","Baja"))) | P20: Baja visión | Q20: — | R20: Parcial | S20: Los afiches heredados conservan texto en la imagen; su alt solo resume el título (plan de mejora).
A21: H-13 | B21: Perceptible | C21: 1.4.10 | D21: Reflow | E21: AA | F21: Sí | G21: Sí | H21: Viewport 320 px | I21: Todas | J21: Parcial | K21: A 320 px el correo del pie se cortaba y el texto de la portada desaparecía. | L21: 2 | M21: 2 | N21: =IF(OR(L21="",M21=""),"",L21*M21) -> 4 | O21: =IF(N21="","",IF(N21>=8,"Alta",IF(N21>=4,"Media","Baja"))) -> Media | P21: Baja visión (lupa), móviles | Q21: AJ-04 | R21: Cumple | S21: 0 px de desplazamiento horizontal a 320 px en 10 páginas, también con espaciado de texto.
A22: H-05 | B22: Perceptible | C22: 1.4.11 | D22: Contraste no textual | E22: AA | F22: Sí | G22: Sí | H22: Cálculo WCAG | I22: Todas | J22: No cumple | K22: Indicador de foco por defecto #4a3b44 sobre la portada oscura: 1.54:1. | L22: 3 | M22: 3 | N22: =IF(OR(L22="",M22=""),"",L22*M22) -> 9 | O22: =IF(N22="","",IF(N22>=8,"Alta",IF(N22>=4,"Media","Baja"))) -> Alta | P22: Baja visión, usuarios de teclado | Q22: AJ-02 | R22: Cumple | S22: Bordes de campos #8a7684 = 4.2:1; halo de foco #ffd84d sobre ciruela = 9.13:1.
A23: H-13 | B23: Perceptible | C23: 1.4.12 | D23: Espaciado del texto | E23: AA | F23: Sí | G23: Sí | H23: Inyección de estilos WCAG | I23: Todas | J23: Parcial | K23: 3 elementos recortados al aplicar el espaciado. | L23: 2 | M23: 2 | N23: =IF(OR(L23="",M23=""),"",L23*M23) -> 4 | O23: =IF(N23="","",IF(N23>=8,"Alta",IF(N23>=4,"Media","Baja"))) -> Media | P23: Dislexia, baja visión | Q23: AJ-04 | R23: Cumple | S23: 0 px de desborde con el espaciado aplicado; ningún texto recortado en los flujos.
A24: — | B24: Perceptible | C24: 1.4.13 | D24: Contenido con hover o foco | E24: AA | F24: Sí | G24: Sí | H24: Manual | I24: Menú principal | J24: Cumple | K24: Los submenús se abren con teclado y aria-expanded. | N24: =IF(OR(L24="",M24=""),"",L24*M24) | O24: =IF(N24="","",IF(N24>=8,"Alta",IF(N24>=4,"Media","Baja"))) | P24: Baja visión, motora | Q24: — | R24: Cumple | S24: Submenú persistente (puente al pasar el puntero) y se cierra con Esc.
A25: H-09 | B25: Operable | C25: 2.1.1 | D25: Teclado | E25: A | F25: Sí | G25: Sí | H25: axe + recorrido con Tab | I25: PT7, PT1 | J25: No cumple | K25: Región desplazable no enfocable (nivel-primaria); botones de galería sin foco. | L25: 3 | M25: 2 | N25: =IF(OR(L25="",M25=""),"",L25*M25) -> 6 | O25: =IF(N25="","",IF(N25>=8,"Alta",IF(N25>=4,"Media","Baja"))) -> Media | P25: Motora, ceguera | Q25: AJ-07 | R25: Cumple | S25: La región desplazable se rehízo como contenido fluido; botones de galería con foco visible; todo se opera con Tab.
A26: — | B26: Operable | C26: 2.1.2 | D26: Sin trampas para el foco | E26: A | F26: No | G26: Sí | H26: Recorrido con Tab | I26: Todas | J26: Sin barrera observada | K26: — | N26: =IF(OR(L26="",M26=""),"",L26*M26) | O26: =IF(N26="","",IF(N26>=8,"Alta",IF(N26>=4,"Media","Baja"))) | P26: — | Q26: — | R26: Cumple | S26: Sin trampas; el visor de imágenes se cierra con Esc.
A27: — | B27: Operable | C27: 2.1.4 | D27: Atajos de teclado por caracteres | E27: A | F27: No | G27: Sí | H27: Manual | I27: Panel de accesibilidad | J27: No aplica | K27: No había atajos. | N27: =IF(OR(L27="",M27=""),"",L27*M27) | O27: =IF(N27="","",IF(N27>=8,"Alta",IF(N27>=4,"Media","Baja"))) | P27: — | Q27: — | R27: Cumple | S27: Los atajos usan modificador (Alt + A, Alt + V).
A28: — | B28: Operable | C28: 2.2.1 | D28: Tiempo ajustable | E28: A | F28: Sí | G28: Sí | H28: Manual | I28: PT3, PT6 | J28: Cumple | K28: No había límites de tiempo. | N28: =IF(OR(L28="",M28=""),"",L28*M28) | O28: =IF(N28="","",IF(N28>=8,"Alta",IF(N28>=4,"Media","Baja"))) | P28: Motora, cognitiva | Q28: AJ-09 | R28: Cumple | S28: Sin límite de tiempo; el borrador se conserva en la sesión.
A29: H-07 | B29: Operable | C29: 2.2.2 | D29: Pausar, detener, ocultar | E29: A | F29: No | G29: Sí | H29: Manual | I29: PT1 | J29: No cumple | K29: Carrusel automático sin control de pausa. | L29: 3 | M29: 2 | N29: =IF(OR(L29="",M29=""),"",L29*M29) -> 6 | O29: =IF(N29="","",IF(N29>=8,"Alta",IF(N29>=4,"Media","Baja"))) -> Media | P29: TDAH, baja visión, lectores de pantalla | Q29: AJ-15 | R29: Cumple | S29: Botón de pausa visible; se detiene con «reducir movimiento».
A30: — | B30: Operable | C30: 2.3.1 | D30: Umbral de tres destellos o menos | E30: A | F30: No | G30: Sí | H30: Manual | I30: Todas | J30: Sin barrera observada | K30: — | N30: =IF(OR(L30="",M30=""),"",L30*M30) | O30: =IF(N30="","",IF(N30>=8,"Alta",IF(N30>=4,"Media","Baja"))) | P30: — | Q30: — | R30: Cumple | S30: Sin destellos.
A31: — | B31: Operable | C31: 2.4.1 | D31: Evitar bloques | E31: A | F31: No | G31: Sí | H31: Recorrido con Tab | I31: Todas | J31: Cumple | K31: Enlace para saltar al contenido. | N31: =IF(OR(L31="",M31=""),"",L31*M31) | O31: =IF(N31="","",IF(N31>=8,"Alta",IF(N31>=4,"Media","Baja"))) | P31: — | Q31: — | R31: Cumple | S31: Enlace «Saltar al contenido» como primer foco.
A32: — | B32: Operable | C32: 2.4.2 | D32: Titulado de páginas | E32: A | F32: No | G32: Sí | H32: Inspección | I32: Todas | J32: Sin barrera observada | K32: — | N32: =IF(OR(L32="",M32=""),"",L32*M32) | O32: =IF(N32="","",IF(N32>=8,"Alta",IF(N32>=4,"Media","Baja"))) | P32: — | Q32: — | R32: Cumple | S32: Títulos únicos; la solicitud indica «Paso N de 3».
A33: — | B33: Operable | C33: 2.4.3 | D33: Orden del foco | E33: A | F33: Sí | G33: Sí | H33: Recorrido con Tab anotado | I33: PT3, PT6 | J33: Cumple | K33: Orden lógico en el menú; tras un error el foco no se movía. | N33: =IF(OR(L33="",M33=""),"",L33*M33) | O33: =IF(N33="","",IF(N33>=8,"Alta",IF(N33>=4,"Media","Baja"))) | P33: Motora, ceguera | Q33: AJ-07 | R33: Cumple | S33: Orden anotado en la solicitud; el foco va al resumen de errores y al título de cada paso.
A34: H-10 | B34: Operable | C34: 2.4.4 | D34: Propósito de los enlaces (en contexto) | E34: A | F34: No | G34: Sí | H34: axe + manual | I34: Actividades, Campus virtual | J34: No cumple | K34: 4 enlaces sin nombre; «Ingresar aquí» repetido. | L34: 2 | M34: 2 | N34: =IF(OR(L34="",M34=""),"",L34*M34) -> 4 | O34: =IF(N34="","",IF(N34>=8,"Alta",IF(N34>=4,"Media","Baja"))) -> Media | P34: Ceguera | Q34: AJ-14 | R34: Cumple | S34: Enlaces con texto que indica el destino.
A35: — | B35: Operable | C35: 2.4.5 | D35: Múltiples vías | E35: AA | F35: No | G35: Sí | H35: Manual | I35: Todas | J35: Sin barrera observada | K35: — | N35: =IF(OR(L35="",M35=""),"",L35*M35) | O35: =IF(N35="","",IF(N35>=8,"Alta",IF(N35>=4,"Media","Baja"))) | P35: — | Q35: — | R35: Cumple | S35: Menú, migas de pan, pie y comandos de voz.
A36: H-04 | B36: Operable | C36: 2.4.6 | D36: Encabezados y etiquetas | E36: AA | F36: No | G36: Sí | H36: Manual | I36: Todas | J36: Parcial | K36: Encabezados sin jerarquía (todos h3). | L36: 3 | M36: 3 | N36: =IF(OR(L36="",M36=""),"",L36*M36) -> 9 | O36: =IF(N36="","",IF(N36>=8,"Alta",IF(N36>=4,"Media","Baja"))) -> Alta | P36: Ceguera, cognitiva | Q36: AJ-03 | R36: Cumple | S36: Encabezados descriptivos y jerárquicos.
A37: H-05 | B37: Operable | C37: 2.4.7 | D37: Foco visible | E37: AA | F37: Sí | G37: Sí | H37: Recorrido con Tab + cálculo | I37: Todas | J37: Parcial | K37: Contorno por defecto poco visible sobre fondos oscuros (1.54:1). | L37: 3 | M37: 3 | N37: =IF(OR(L37="",M37=""),"",L37*M37) -> 9 | O37: =IF(N37="","",IF(N37>=8,"Alta",IF(N37>=4,"Media","Baja"))) -> Alta | P37: Motora (teclado), baja visión | Q37: AJ-06 | R37: Cumple | S37: Doble anillo ciruela + halo amarillo visible en fondos claros y oscuros.
A38: — | B38: Operable | C38: 2.5.1 | D38: Gestos del puntero | E38: A | F38: Sí | G38: Sí | H38: Manual | I38: PT1 | J38: Cumple | K38: El carrusel tenía flechas. | N38: =IF(OR(L38="",M38=""),"",L38*M38) | O38: =IF(N38="","",IF(N38>=8,"Alta",IF(N38>=4,"Media","Baja"))) | P38: Motora | Q38: — | R38: Cumple | S38: Sin gestos multipunto ni de trayectoria; botones anterior, siguiente y pausa.
A39: — | B39: Operable | C39: 2.5.2 | D39: Cancelación del puntero | E39: A | F39: No | G39: Sí | H39: Manual | I39: Todas | J39: Sin barrera observada | K39: — | N39: =IF(OR(L39="",M39=""),"",L39*M39) | O39: =IF(N39="","",IF(N39>=8,"Alta",IF(N39>=4,"Media","Baja"))) | P39: — | Q39: — | R39: Cumple | S39: Activación al soltar (eventos nativos de click).
A40: — | B40: Operable | C40: 2.5.3 | D40: Etiqueta en el nombre | E40: A | F40: Sí | G40: Sí | H40: Script de comparación etiqueta / aria-label | I40: Todas | J40: Cumple | K40: Sin discrepancias en el flujo. | N40: =IF(OR(L40="",M40=""),"",L40*M40) | O40: =IF(N40="","",IF(N40>=8,"Alta",IF(N40>=4,"Media","Baja"))) | P40: Motora (control por voz) | Q40: AJ-08 | R40: Cumple | S40: 0 discrepancias en 10 páginas; «Editar» → «Editar datos del estudiante».
A41: — | B41: Operable | C41: 2.5.4 | D41: Activación mediante movimiento | E41: A | F41: No | G41: No | H41: Manual | I41: No hay funciones activadas por movimiento. | J41: No aplica | K41: — | N41: =IF(OR(L41="",M41=""),"",L41*M41) | O41: =IF(N41="","",IF(N41>=8,"Alta",IF(N41>=4,"Media","Baja"))) | P41: — | Q41: — | R41: No aplica | S41: —
...

Sheet Resumen POUR
A1: Resumen por principio (POUR) — calculado desde la matriz
A4: Principio | B4: Total | C4: v2.0 Cumple* | D4: v2.0 Parcial | E4: v2.0 No cumple | F4: v2.0 No aplica | G4: v3.0 Cumple | H4: v3.0 Parcial | I4: v3.0 No cumple | J4: v3.0 No aplica | K4: Estado v3.0
A5: Perceptible | B5: =COUNTIF('Matriz WCAG 2.1'!$B$5:$B$54,A5) -> 20 | C5: =COUNTIFS('Matriz WCAG 2.1'!$B$5:$B$54,A5,'Matriz WCAG 2.1'!$J$5:$J$54,"Cumple")+COUNTIFS('Matriz WCAG 2.1'!$B$5:$B$54,A5,'Matriz WCAG 2.1'!$J$5:$J$54,"Sin barrera observada") -> 6 | D5: =COUNTIFS('Matriz WCAG 2.1'!$B$5:$B$54,A5,'Matriz WCAG 2.1'!$J$5:$J$54,"Parcial") -> 5 | E5: =COUNTIFS('Matriz WCAG 2.1'!$B$5:$B$54,A5,'Matriz WCAG 2.1'!$J$5:$J$54,"No cumple") -> 7 | F5: =COUNTIFS('Matriz WCAG 2.1'!$B$5:$B$54,A5,'Matriz WCAG 2.1'!$J$5:$J$54,"No aplica") -> 2 | G5: =COUNTIFS('Matriz WCAG 2.1'!$B$5:$B$54,A5,'Matriz WCAG 2.1'!$R$5:$R$54,"Cumple") -> 14 | H5: =COUNTIFS('Matriz WCAG 2.1'!$B$5:$B$54,A5,'Matriz WCAG 2.1'!$R$5:$R$54,"Parcial") -> 2 | I5: =COUNTIFS('Matriz WCAG 2.1'!$B$5:$B$54,A5,'Matriz WCAG 2.1'!$R$5:$R$54,"No cumple") -> 2 | J5: =COUNTIFS('Matriz WCAG 2.1'!$B$5:$B$54,A5,'Matriz WCAG 2.1'!$R$5:$R$54,"No aplica") -> 2 | K5: =IF(H5+I5=0,"Cumple","Parcialmente conforme") -> Parcialmente conforme
A6: Operable | B6: =COUNTIF('Matriz WCAG 2.1'!$B$5:$B$54,A6) -> 17 | C6: =COUNTIFS('Matriz WCAG 2.1'!$B$5:$B$54,A6,'Matriz WCAG 2.1'!$J$5:$J$54,"Cumple")+COUNTIFS('Matriz WCAG 2.1'!$B$5:$B$54,A6,'Matriz WCAG 2.1'!$J$5:$J$54,"Sin barrera observada") -> 10 | D6: =COUNTIFS('Matriz WCAG 2.1'!$B$5:$B$54,A6,'Matriz WCAG 2.1'!$J$5:$J$54,"Parcial") -> 2 | E6: =COUNTIFS('Matriz WCAG 2.1'!$B$5:$B$54,A6,'Matriz WCAG 2.1'!$J$5:$J$54,"No cumple") -> 3 | F6: =COUNTIFS('Matriz WCAG 2.1'!$B$5:$B$54,A6,'Matriz WCAG 2.1'!$J$5:$J$54,"No aplica") -> 2 | G6: =COUNTIFS('Matriz WCAG 2.1'!$B$5:$B$54,A6,'Matriz WCAG 2.1'!$R$5:$R$54,"Cumple") -> 16 | H6: =COUNTIFS('Matriz WCAG 2.1'!$B$5:$B$54,A6,'Matriz WCAG 2.1'!$R$5:$R$54,"Parcial") -> 0 | I6: =COUNTIFS('Matriz WCAG 2.1'!$B$5:$B$54,A6,'Matriz WCAG 2.1'!$R$5:$R$54,"No cumple") -> 0 | J6: =COUNTIFS('Matriz WCAG 2.1'!$B$5:$B$54,A6,'Matriz WCAG 2.1'!$R$5:$R$54,"No aplica") -> 1 | K6: =IF(H6+I6=0,"Cumple","Parcialmente conforme") -> Cumple
A7: Comprensible | B7: =COUNTIF('Matriz WCAG 2.1'!$B$5:$B$54,A7) -> 10 | C7: =COUNTIFS('Matriz WCAG 2.1'!$B$5:$B$54,A7,'Matriz WCAG 2.1'!$J$5:$J$54,"Cumple")+COUNTIFS('Matriz WCAG 2.1'!$B$5:$B$54,A7,'Matriz WCAG 2.1'!$J$5:$J$54,"Sin barrera observada") -> 5 | D7: =COUNTIFS('Matriz WCAG 2.1'!$B$5:$B$54,A7,'Matriz WCAG 2.1'!$J$5:$J$54,"Parcial") -> 1 | E7: =COUNTIFS('Matriz WCAG 2.1'!$B$5:$B$54,A7,'Matriz WCAG 2.1'!$J$5:$J$54,"No cumple") -> 3 | F7: =COUNTIFS('Matriz WCAG 2.1'!$B$5:$B$54,A7,'Matriz WCAG 2.1'!$J$5:$J$54,"No aplica") -> 1 | G7: =COUNTIFS('Matriz WCAG 2.1'!$B$5:$B$54,A7,'Matriz WCAG 2.1'!$R$5:$R$54,"Cumple") -> 10 | H7: =COUNTIFS('Matriz WCAG 2.1'!$B$5:$B$54,A7,'Matriz WCAG 2.1'!$R$5:$R$54,"Parcial") -> 0 | I7: =COUNTIFS('Matriz WCAG 2.1'!$B$5:$B$54,A7,'Matriz WCAG 2.1'!$R$5:$R$54,"No cumple") -> 0 | J7: =COUNTIFS('Matriz WCAG 2.1'!$B$5:$B$54,A7,'Matriz WCAG 2.1'!$R$5:$R$54,"No aplica") -> 0 | K7: =IF(H7+I7=0,"Cumple","Parcialmente conforme") -> Cumple
A8: Robusto | B8: =COUNTIF('Matriz WCAG 2.1'!$B$5:$B$54,A8) -> 3 | C8: =COUNTIFS('Matriz WCAG 2.1'!$B$5:$B$54,A8,'Matriz WCAG 2.1'!$J$5:$J$54,"Cumple")+COUNTIFS('Matriz WCAG 2.1'!$B$5:$B$54,A8,'Matriz WCAG 2.1'!$J$5:$J$54,"Sin barrera observada") -> 1 | D8: =COUNTIFS('Matriz WCAG 2.1'!$B$5:$B$54,A8,'Matriz WCAG 2.1'!$J$5:$J$54,"Parcial") -> 0 | E8: =COUNTIFS('Matriz WCAG 2.1'!$B$5:$B$54,A8,'Matriz WCAG 2.1'!$J$5:$J$54,"No cumple") -> 2 | F8: =COUNTIFS('Matriz WCAG 2.1'!$B$5:$B$54,A8,'Matriz WCAG 2.1'!$J$5:$J$54,"No aplica") -> 0 | G8: =COUNTIFS('Matriz WCAG 2.1'!$B$5:$B$54,A8,'Matriz WCAG 2.1'!$R$5:$R$54,"Cumple") -> 3 | H8: =COUNTIFS('Matriz WCAG 2.1'!$B$5:$B$54,A8,'Matriz WCAG 2.1'!$R$5:$R$54,"Parcial") -> 0 | I8: =COUNTIFS('Matriz WCAG 2.1'!$B$5:$B$54,A8,'Matriz WCAG 2.1'!$R$5:$R$54,"No cumple") -> 0 | J8: =COUNTIFS('Matriz WCAG 2.1'!$B$5:$B$54,A8,'Matriz WCAG 2.1'!$R$5:$R$54,"No aplica") -> 0 | K8: =IF(H8+I8=0,"Cumple","Parcialmente conforme") -> Cumple
A9: Total | B9: =SUM(B5:B8) -> 50 | C9: =SUM(C5:C8) -> 22 | D9: =SUM(D5:D8) -> 8 | E9: =SUM(E5:E8) -> 15 | F9: =SUM(F5:F8) -> 5 | G9: =SUM(G5:G8) -> 43 | H9: =SUM(H5:H8) -> 2 | I9: =SUM(I5:I8) -> 2 | J9: =SUM(J5:J8) -> 3 | K9: =IF(H9+I9=0,"Conforme AA","Parcialmente conforme") -> Parcialmente conforme
A11: * En v2.0, «Cumple» incluye los criterios no núcleo sin barrera observada.
A12: Núcleo evaluados (26): | B12: =COUNTIF('Matriz WCAG 2.1'!$F$5:$F$54,"Sí") -> 26

Sheet Hallazgos
A1: Hallazgos priorizados (v2.0) y estado en v3.0
A4: ID | B4: Hallazgo | C4: Criterio(s) | D4: Pantalla | E4: Evidencia (medición) | F4: S | G4: A | H4: Prioridad (S×A) | I4: Categoría | J4: Perfiles | K4: Ajuste | L4: Estado v3.0
A5: H-01 | B5: Texto ilegible en las tarjetas de accesos rápidos | C5: 1.4.3 | D5: Inicio | E5: 1.53 a 1.86:1 (mínimo 4.5:1) | F5: 4 | G5: 3 | H5: =F5*G5 -> 12 | I5: =IF(H5>=8,"Alta",IF(H5>=4,"Media","Baja")) -> Alta | J5: Baja visión, adultos mayores | K5: AJ-01 | L5: Resuelto
A6: H-02 | B6: Errores del formulario sin explicación ni sugerencia | C6: 3.3.1, 3.3.3 | D6: Contáctenos | E6: Avisos nativos en inglés; sin aria-invalid | F6: 4 | G6: 3 | H6: =F6*G6 -> 12 | I6: =IF(H6>=8,"Alta",IF(H6>=4,"Media","Baja")) -> Alta | J6: Ceguera, cognitiva | K6: AJ-11 | L6: Resuelto
A7: H-03 | B7: Imágenes informativas sin texto alternativo | C7: 1.1.1 | D7: Inicio, Municipio | E7: 81/169 y 180/268 con alt vacío | F7: 3 | G7: 3 | H7: =F7*G7 -> 9 | I7: =IF(H7>=8,"Alta",IF(H7>=4,"Media","Baja")) -> Alta | J7: Ceguera | K7: AJ-03 | L7: Resuelto
A8: H-04 | B8: Estructura de encabezados rota | C8: 1.3.1, 2.4.6 | D8: Todas | E8: Sin h1 o con 14 a 17 h1 | F8: 3 | G8: 3 | H8: =F8*G8 -> 9 | I8: =IF(H8>=8,"Alta",IF(H8>=4,"Media","Baja")) -> Alta | J8: Ceguera, cognitiva | K8: AJ-03 | L8: Resuelto
A9: H-05 | B9: Indicador de foco casi invisible | C9: 2.4.7, 1.4.11 | D9: Todas | E9: Contorno 1.54:1 sobre fondo oscuro | F9: 3 | G9: 3 | H9: =F9*G9 -> 9 | I9: =IF(H9>=8,"Alta",IF(H9>=4,"Media","Baja")) -> Alta | J9: Teclado, baja visión | K9: AJ-02, AJ-06 | L9: Resuelto
A10: H-06 | B10: Envío y errores no anunciados | C10: 4.1.3 | D10: Contáctenos | E10: Sin role=status ni aria-live | F10: 3 | G10: 3 | H10: =F10*G10 -> 9 | I10: =IF(H10>=8,"Alta",IF(H10>=4,"Media","Baja")) -> Alta | J10: Ceguera | K10: AJ-12 | L10: Resuelto
A11: H-07 | B11: Carrusel automático sin pausa | C11: 2.2.2 | D11: Inicio | E11: Rotación sin control | F11: 3 | G11: 2 | H11: =F11*G11 -> 6 | I11: =IF(H11>=8,"Alta",IF(H11>=4,"Media","Baja")) -> Media | J11: TDAH, baja visión | K11: AJ-15 | L11: Resuelto
A12: H-08 | B12: Controles sin nombre accesible | C12: 4.1.2 | D12: Inicio, Municipio | E12: 6 iframes sin title; 15 aria prohibidos | F12: 3 | G12: 2 | H12: =F12*G12 -> 6 | I12: =IF(H12>=8,"Alta",IF(H12>=4,"Media","Baja")) -> Media | J12: Ceguera, control por voz | K12: AJ-08 | L12: Resuelto
A13: H-09 | B13: Contenido que no se alcanza con teclado | C13: 2.1.1 | D13: Nivel Primaria, galerías | E13: Región desplazable sin foco | F13: 3 | G13: 2 | H13: =F13*G13 -> 6 | I13: =IF(H13>=8,"Alta",IF(H13>=4,"Media","Baja")) -> Media | J13: Motora, ceguera | K13: AJ-07 | L13: Resuelto
A14: H-10 | B14: Enlaces sin propósito claro | C14: 2.4.4 | D14: Actividades, Campus | E14: 4 sin nombre; «Ingresar aquí» repetido | F14: 2 | G14: 2 | H14: =F14*G14 -> 4 | I14: =IF(H14>=8,"Alta",IF(H14>=4,"Media","Baja")) -> Media | J14: Ceguera | K14: AJ-14 | L14: Resuelto
A15: H-11 | B15: Widget overlay en inglés | C15: 3.1.2 | D15: Todas | E15: Textos en inglés sin lang | F15: 2 | G15: 3 | H15: =F15*G15 -> 6 | I15: =IF(H15>=8,"Alta",IF(H15>=4,"Media","Baja")) -> Media | J15: Ceguera, cognitiva | K15: AJ-14 | L15: Resuelto
A16: H-12 | B16: Campos sin propósito ni formato | C16: 1.3.5, 3.3.2 | D16: Contáctenos | E16: Sin autocomplete; celular type=text | F16: 2 | G16: 2 | H16: =F16*G16 -> 4 | I16: =IF(H16>=8,"Alta",IF(H16>=4,"Media","Baja")) -> Media | J16: Motora, cognitiva | K16: AJ-10, AJ-12 | L16: Resuelto
... A20: H-16 | B20: Texto del pie con contraste bajo | C20: 1.4.3 | D20: Pie global | E20: 3.75:1 | F20: 2 | G20: 3 | H20: =F20*G20 -> 6 | I20: =IF(H20>=8,"Alta",IF(H20>=4,"Media","Baja")) -> Media | J20: Baja visión | K20: AJ-01 | L20: Resuelto
A22: Alta resueltos: | C22: =COUNTIFS(I5:I20,"Alta",L5:L20,"Resuelto")&" de "&COUNTIF(I5:I20,"Alta") -> 6 de 6
A23: Media resueltos o con plan: | C23: =TEXT(COUNTIF(I5:I20,"Media")/COUNTIF(I5:I20,"Media"),"0%")&" ("&COUNTIFS(I5:I20,"Media",L5:L20,"Resuelto")&" de "&COUNTIF(I5:I20,"Media")&" resueltos)" -> 100% (9 de 9 resueltos)

Sheet Trazabilidad
A1: Trazabilidad hallazgo → criterio → ajuste → evidencia (15 ajustes: 5 por categoría)
A4: Ajuste | B4: Categoría | C4: Hallazgo | D4: Criterio WCAG | E4: Antes (v2.0) | F4: Después (v3.0) | G4: Evidencia
A5: AJ-01 | B5: Sensorial | C5: H-01, H-16 | D5: 1.4.3 | E5: Texto claro sobre degradado rosa (1.53:1); pie 3.75:1 | F5: Tarjetas blancas con texto ciruela 12.63:1 y secundario 6.26:1; velo de la portada reforzado para ≥ 4.5:1 sobre cualquier foto | G5: Fig. 1; contraste calculado
A6: AJ-02 | B6: Sensorial | C6: H-05 | D6: 1.4.11 | E6: Bordes y foco sin contraste suficiente | F6: Borde de campos #8a7684 (4.2:1); halo de foco 9.13:1 | G6: Fig. 2
A7: AJ-03 | B7: Sensorial | C7: H-03, H-04 | D7: 1.1.1, 1.3.1 | E7: Alt vacío en fotos informativas; sin h1 | F7: Alt descriptivo; un h1 y jerarquía sin saltos | G7: axe 0; auditoría de encabezados
A8: AJ-04 | B8: Sensorial | C8: H-13 | D8: 1.4.4, 1.4.10, 1.4.12 | E8: Correo cortado y texto oculto en móvil | F8: Ajuste de líneas, 0 px de desborde a 320 px y 200 % | G8: Fig. 3
A9: AJ-05 | B9: Sensorial | C9: H-15 | D9: 1.4.1, 1.2.2 | E9: Videos sin subtítulos activos; estados solo nativos | F9: Subtítulos activos por defecto; errores con texto y no solo color; corrección de daltonismo | G9: Fig. 1 (simulación)
A10: AJ-06 | B10: Motora | C10: H-05 | D10: 2.4.7 | E10: Contorno por defecto 1.54:1 | F10: Doble anillo ciruela + halo amarillo en todos los controles | G10: Fig. 2
A11: AJ-07 | B11: Motora | C11: H-09 | D11: 2.1.1, 2.4.3 | E11: Región y botones sin foco | F11: Todo operable con Tab; orden anotado; foco gestionado tras errores | G11: Fig. C1; Anexo D
A12: AJ-08 | B12: Motora | C12: H-08, H-14 | D12: 2.5.3, 4.1.2, buena práctica 44 px | E12: Controles de 21 px; nombres que no coinciden | F12: Menú, opciones y botones ≥ 44 px; nombre accesible que empieza por la etiqueta visible; control por voz | G12: Auditoría de tamaños
A13: AJ-09 | B13: Motora | C13: — | D13: 2.2.1 | E13: Formulario sin borrador | F13: Sin límite de tiempo; borrador en la sesión y botón para borrarlo | G13: Prueba funcional
A14: AJ-10 | B14: Motora | C14: H-12 | D14: 1.3.5 | E14: Escritura completa de cada dato | F14: autocomplete y teclado numérico para el celular | G14: Inspección de código
A15: AJ-11 | B15: Cognitiva | C15: H-02 | D15: 3.3.1, 3.3.3 | E15: Aviso nativo en inglés | F15: Mensaje con causa y ejemplo; resumen de errores enlazado | G15: Fig. 4; Anexo D
... A19: AJ-15 | B19: Cognitiva | C19: H-07 | D19: 2.2.2 | E19: Carrusel que no se detiene | F19: Botón de pausa y respeto a «reducir movimiento» | G19: Prueba funcional
A21: Por categoría:
A22: Sensorial | B22: =COUNTIF(B5:B19,A22) -> 5
A23: Motora | B23: =COUNTIF(B5:B19,A23) -> 5
A24: Cognitiva | B24: =COUNTIF(B5:B19,A24) -> 5

Sheet WCAG 2.2 (B3)
A1: Auditoría adicional de criterios nuevos de WCAG 2.2 sobre la v3.0 (bonificación B3)
A4: Criterio | B4: Nombre | C4: Nivel | D4: Resultado v3.0 | E4: Evidencia
A5: 2.4.11 | B5: Foco no oculto (mínimo) | C5: AA | D5: Cumple | E5: El botón flotante de accesibilidad se redujo a 56 px y se añadió scroll-padding (88 px abajo y 96 px arriba); el control enfocado no queda tapado.
A6: 2.5.7 | B6: Movimientos de arrastre | C6: AA | D6: No aplica | E6: Ninguna función requiere arrastrar; el control deslizante del panel también se opera con flechas.
A7: 2.5.8 | B7: Tamaño del objetivo (mínimo) | C7: AA | D7: Cumple | E7: Controles del flujo ≥ 24 × 24 px (barra superior a 24 px; menú y opciones a 44 px); los enlaces dentro de párrafos están exentos.
A8: 3.2.6 | B8: Ayuda consistente | C8: A | D8: Cumple | E8: Teléfonos, correo y «Opciones de accesibilidad» en la barra superior, y contacto en el pie, en el mismo lugar de las 19 páginas.
A9: 3.3.7 | B9: Entrada redundante | C9: A | D9: Cumple | E9: La revisión muestra lo ya escrito; anular conserva los datos; el borrador evita reescribir.
A10: 3.3.8 | B10: Autenticación accesible (mínimo) | C10: AA | D10: No aplica | E10: El flujo no tiene inicio de sesión; los campus virtuales externos quedan fuera del alcance.

Sheet Línea base APF2 (EJEMPLO)
A1: Línea base del APF2 — DATOS DE EJEMPLO: reemplazar con las métricas reales del APF2
A2: Celdas amarillas = editar. La comparación de la hoja Validación usa estas celdas.
A4: Tarea | B4: Éxito APF2 (%) | C4: Mediana de tiempo APF2 (s) | D4: n
A5: T1 | B5: 0.6 | C5: 95 | D5: 5
A6: T2 | B6: 0.8 | C6: 70 | D6: 5
A7: T3 | B7: 0.4 | C7: 210 | D7: 5
A8: SUS promedio | B8: 61.5 | D8: 5

Sheet Validación (EJEMPLO)
A1: Validación con participantes v3.0 — DATOS DE EJEMPLO: reemplazar con las sesiones reales
A2: Resultado: S = completa sin ayuda, P = parcial, N = no completa. SEQ 1–7. Celdas amarillas = editar; el resto son fórmulas.
A4: Participante | B4: Perfil | C4: Descripción | D4: Tecnología / condición de prueba | E4: Tipo | F4: Edad
A5: P1 | B5: Visual | C5: Baja visión; madre de familia | D5: Zoom 200 % + alto contraste del panel | E5: Condición real (ejemplo) | F5: 58
A6: P2 | B6: Visual | C6: Ceguera; usuario habitual de lector | D6: NVDA 2025 + Firefox, solo teclado | E6: Tecnología de apoyo habitual (ejemplo) | F6: 34
A7: P3 | B7: Visual | C7: Daltonismo (deuteranopía) | D7: Sin ayuda; corrección de color del panel | E7: Condición real (ejemplo) | F7: 22
A8: P4 | B8: Motor | C8: Uso con una mano, sin mouse | D8: Solo teclado (mano dominante inmovilizada) | E8: Simulación declarada | F8: 21
A9: P5 | B9: Auditivo | C9: Hipoacusia | D9: Sin audio; subtítulos | E9: Condición real (ejemplo) | F9: 41
A10: P6 | B10: Cognitivo | C10: Baja alfabetización digital; adulto mayor | D10: Sin límite de tiempo; lectura en voz alta | E10: Condición real (ejemplo) | F10: 67
A12: Resultados por tarea
A13: Tarea | B13: Participante | C13: Resultado (S/P/N) | D13: Tiempo (s) | E13: Errores | F13: SEQ (1-7)
A14: T1 | B14: P1 | C14: S | D14: 78 | E14: 0 | F14: 6
A15: T1 | B15: P2 | C15: S | D15: 142 | E15: 1 | F15: 5
A16: T1 | B16: P3 | C16: S | D16: 41 | E16: 0 | F16: 7
A17: T1 | B17: P4 | C17: S | D17: 66 | E17: 0 | F17: 6
A18: T1 | B18: P5 | C18: S | D18: 38 | E18: 0 | F18: 7
A19: T1 | B19: P6 | C19: P | D19: 121 | E19: 2 | F19: 4
A20: T2 | B20: P1 | C20: S | D20: 64 | E20: 0 | F20: 6
A21: T2 | B21: P2 | C21: S | D21: 118 | E21: 0 | F21: 5
A22: T2 | B22: P3 | C22: S | D22: 35 | E22: 0 | F22: 7
A23: T2 | B23: P4 | C23: S | D23: 52 | E23: 0 | F23: 6
A24: T2 | B24: P5 | C24: S | D24: 33 | E24: 0 | F24: 7
A25: T2 | B25: P6 | C25: S | D25: 97 | E25: 1 | F25: 5
... A37: T4 | B37: P6 | C37: S | D37: 133 | E37: 2 | F37: 5
A39: Resumen por tarea y comparación con APF2
A40: Tarea | B40: Éxito v3.0 | C40: Éxito APF2 | D40: Diferencia (p.p.) | E40: Mediana tiempo v3.0 (s) | F40: Mediana APF2 (s) | G40: SEQ promedio | H40: Errores promedio
A41: T1 | B41: =COUNTIFS($A$14:$A$37,A41,$C$14:$C$37,"S")/COUNTIF($A$14:$A$37,A41) -> 0.83333333 | C41: ='Línea base APF2 (EJEMPLO)'!B5 -> 0.6 | D41: =(B41-C41)*100 -> 23.333333 | E41: {=MEDIAN(IF($A$14:$A$37=A41,$D$14:$D$37))} -> 72 | F41: ='Línea base APF2 (EJEMPLO)'!C5 -> 95 | G41: =AVERAGEIF($A$14:$A$37,A41,$F$14:$F$37) -> 5.8333333 | H41: =AVERAGEIF($A$14:$A$37,A41,$E$14:$E$37) -> 0.5
A42: T2 | B42: =COUNTIFS($A$14:$A$37,A42,$C$14:$C$37,"S")/COUNTIF($A$14:$A$37,A42) -> 1 | C42: ='Línea base APF2 (EJEMPLO)'!B6 -> 0.8 | D42: =(B42-C42)*100 -> 20 | E42: {=MEDIAN(IF($A$14:$A$37=A42,$D$14:$D$37))} -> 58 | F42: ='Línea base APF2 (EJEMPLO)'!C6 -> 70 | G42: =AVERAGEIF($A$14:$A$37,A42,$F$14:$F$37) -> 6 | H42: =AVERAGEIF($A$14:$A$37,A42,$E$14:$E$37) -> 0.16666667
A43: T3 | B43: =COUNTIFS($A$14:$A$37,A43,$C$14:$C$37,"S")/COUNTIF($A$14:$A$37,A43) -> 1 | C43: ='Línea base APF2 (EJEMPLO)'!B7 -> 0.4 | D43: =(B43-C43)*100 -> 60 | E43: {=MEDIAN(IF($A$14:$A$37=A43,$D$14:$D$37))} -> 141.5 | F43: ='Línea base APF2 (EJEMPLO)'!C7 -> 210 | G43: =AVERAGEIF($A$14:$A$37,A43,$F$14:$F$37) -> 5 | H43: =AVERAGEIF($A$14:$A$37,A43,$E$14:$E$37) -> 1
A44: T4 | B44: =COUNTIFS($A$14:$A$37,A44,$C$14:$C$37,"S")/COUNTIF($A$14:$A$37,A44) -> 0.83333333 | C44: n. a. (tarea nueva) | D44: — | E44: {=MEDIAN(IF($A$14:$A$37=A44,$D$14:$D$37))} -> 85 | F44: — | G44: =AVERAGEIF($A$14:$A$37,A44,$F$14:$F$37) -> 5.6666667 | H44: =AVERAGEIF($A$14:$A$37,A44,$E$14:$E$37) -> 1.3333333
A45: Global | B45: =COUNTIF($C$14:$C$37,"S")/COUNTA($C$14:$C$37) -> 0.91666667
A47: SUS por participante (ítems 1–10, escala 1–5)
A48: Participante | B48: Í1 | C48: Í2 | D48: Í3 | E48: Í4 | F48: Í5 | G48: Í6 | H48: Í7 | I48: Í8 | J48: Í9 | K48: Í10 | L48: SUS
A49: P1 | B49: 5 | C49: 2 | D49: 4 | E49: 2 | F49: 4 | G49: 2 | H49: 4 | I49: 2 | J49: 4 | K49: 2 | L49: =2.5*((B49-1)+(5-C49)+(D49-1)+(5-E49)+(F49-1)+(5-G49)+(H49-1)+(5-I49)+(J49-1)+(5-K49)) -> 77.5
A50: P2 | B50: 3 | C50: 3 | D50: 4 | E50: 2 | F50: 4 | G50: 2 | H50: 4 | I50: 2 | J50: 4 | K50: 2 | L50: =2.5*((B50-1)+(5-C50)+(D50-1)+(5-E50)+(F50-1)+(5-G50)+(H50-1)+(5-I50)+(J50-1)+(5-K50)) -> 70
A51: P3 | B51: 5 | C51: 1 | D51: 5 | E51: 1 | F51: 5 | G51: 2 | H51: 4 | I51: 2 | J51: 4 | K51: 2 | L51: =2.5*((B51-1)+(5-C51)+(D51-1)+(5-E51)+(F51-1)+(5-G51)+(H51-1)+(5-I51)+(J51-1)+(5-K51)) -> 87.5
A52: P4 | B52: 5 | C52: 1 | D52: 4 | E52: 2 | F52: 4 | G52: 2 | H52: 4 | I52: 2 | J52: 4 | K52: 2 | L52: =2.5*((B52-1)+(5-C52)+(D52-1)+(5-E52)+(F52-1)+(5-G52)+(H52-1)+(5-I52)+(J52-1)+(5-K52)) -> 80
A53: P5 | B53: 5 | C53: 1 | D53: 5 | E53: 1 | F53: 5 | G53: 1 | H53: 4 | I53: 2 | J53: 4 | K53: 2 | L53: =2.5*((B53-1)+(5-C53)+(D53-1)+(5-E53)+(F53-1)+(5-G53)+(H53-1)+(5-I53)+(J53-1)+(5-K53)) -> 90
A54: P6 | B54: 3 | C54: 3 | D54: 3 | E54: 2 | F54: 4 | G54: 2 | H54: 4 | I54: 2 | J54: 4 | K54: 2 | L54: =2.5*((B54-1)+(5-C54)+(D54-1)+(5-E54)+(F54-1)+(5-G54)+(H54-1)+(5-I54)+(J54-1)+(5-K54)) -> 67.5
A55: Promedio v3.0 | L55: =AVERAGE(L49:L54) -> 78.75
...

Sheet Barreras residuales (EJEMPLO)
A1: Barreras residuales observadas — DATOS DE EJEMPLO
A4: ID | B4: Participante | C4: Tarea | D4: Barrera | E4: Criterio | F4: Severidad | G4: Plan
A5: B-01 | B5: P2 | C5: T4 | D5: El campo de fecha se anuncia como tres segmentos (día, mes, año) sin instrucciones de formato audibles al entrar a cada uno. | E5: 1.3.1, 3.3.2 | F5: 2 | G5: Sustituir por tres listas (día, mes, año) o un campo de texto con formato dd/mm/aaaa.
A6: B-02 | B6: P6 | C6: T1 | D6: Buscó «Horarios» en «Nosotros» antes de hallarlo en «Campus virtual». | E6: 3.2.3 (arquitectura) | F6: 2 | G6: Agregar «Horarios de clase» a los accesos rápidos de Inicio y prueba de árbol (tree test).
A7: B-03 | B7: P5 | C7: — | D7: Los subtítulos automáticos del video tienen errores en nombres propios. | E7: 1.2.2 | F7: 2 | G7: Subir subtítulos revisados (.srt) al canal de YouTube.
A8: B-04 | B8: P2 | C8: T3 | D8: Después del envío correcto no sabía si debía esperar una respuesta por correo o por teléfono. | E8: 3.3.2 | F8: 1 | G8: Indicar en el mensaje de éxito el medio y el plazo de respuesta, como en la solicitud.
A9: B-05 | B9: P1 | C9: T2 | D9: Con alto contraste y 175 % de texto, el nombre del PDF ocupaba tres líneas y perdía la extensión. | E9: 1.4.10 | F9: 1 | G9: Mostrar formato y tamaño en una línea aparte («PDF, 240 KB»).
